<sdf version='1.3'>
  <model name='AutoNOMOS_mini'>
    <link name='base_link'>
      <pose>0.000000 0.000000 0.000000 0.000000 0.000000 0.000000</pose>
      <inertial>
        <pose>0.002623 0.000000 0.022951 0.000000 0.000000 0.000000</pose>
        <mass>0.610000</mass>
        <inertia>
          <ixx>0.611350</ixx>
          <ixy>0.000000</ixy>
          <ixz>0.000160</ixz>
          <iyy>0.611606</iyy>
          <iyz>0.000000</iyz>
          <izz>0.610256</izz>
        </inertia>
      </inertial>
      <collision name='base_link_geom'>
        <pose>0.000000 0.000000 0.000000 0.000000 0.000000 0.000000</pose>
        <geometry>
          <box>
            <size>0.400000 0.150000 0.09500000</size>
          </box>
        </geometry>
        <surface>
          <contact>
            <ode/>
          </contact>
          <friction>
            <ode/>
          </friction>
        </surface>
      </collision>

      <collision name='base_link_geom_front_link'>
        <pose>0.160000 0.000000 -0.0500000 0.000000 0.000000 0.000000</pose>
        <geometry>
          <box>
            <size>0.020000 0.150000 0.005000</size>
          </box>
        </geometry>
        <surface>
          <contact>
            <ode/>
          </contact>
          <friction>
            <ode/>
          </friction>
        </surface>
        <surface>
          <contact>
            <ode/>
          </contact>
          <friction>
            <ode/>
          </friction>
        </surface>
      </collision>

      <collision name='base_link_geom_laser_base_link'>
        <pose>0.000000 0.000000 0.075000 0.000000 0.000000 0.000000</pose>
        <geometry>
          <box>
            <size>0.050000 0.050000 0.050000</size>
          </box>
        </geometry>
        <surface>
          <contact>
            <ode/>
          </contact>
          <friction>
            <ode/>
          </friction>
        </surface>
      </collision>

      <visual name='base_link_visual'>
        <pose>0.000000 0.000000 0.000000 0.000000 0.000000 0.000000</pose>
        <geometry>
          <box>
            <size>0.400000 0.150000 0.09500000</size>
          </box>
        </geometry>
        <material>
          <script>
            <name>Gazebo/Green</name>
          </script>
        </material>
      </visual>
      <!-- <visual name='base_link_visualbase_scan_link'>
        <pose>0.000000 0.000000 0.114000 0.000000 0.000000 0.000000</pose>
        <geometry>
          <cylinder>
            <length>0.028000</length>
            <radius>0.022900</radius>
          </cylinder>
        </geometry>
        <material>
          <script>
            <name>Gazebo/Green</name>
          </script>
        </material>
      </visual> -->
      <visual name='base_link_visualfront_link'>
        <pose>0.160000 0.000000 -0.0500000 0.000000 0.000000 0.000000</pose>
        <geometry>
          <box>
            <size>0.020000 0.150000 0.005000</size>
          </box>
        </geometry>
        <material>
          <script>
            <name>Gazebo/Red</name>
          </script>
        </material>
        <material>
          <script>
            <name>Gazebo/Red</name>
          </script>
        </material>
      </visual>

      <visual name='base_link_visuallaser_base_link'>
        <pose>0.000000 0.000000 0.07000 0.000000 0.000000 0.000000</pose>
        <geometry>
          <cylinder>
            <!-- <size>0.050000 0.050000 0.050000</size> -->
            <radius> 0.025</radius>
            <length> 0.05 </length>
          </cylinder>
        </geometry>
        <material>
          <script>
            <name>Gazebo/Green</name>
          </script>
        </material>
      </visual>

      <velocity_decay>
        <linear>0.000000</linear>
        <angular>0.000000</angular>
      </velocity_decay>

      <velocity_decay>
        <linear>0.000000</linear>
        <angular>0.000000</angular>
      </velocity_decay>

      <velocity_decay>
        <linear>0.000000</linear>
        <angular>0.000000</angular>
      </velocity_decay>

      <velocity_decay>
        <linear>0.000000</linear>
        <angular>0.000000</angular>
      </velocity_decay>

      <velocity_decay>
        <linear>0.000000</linear>
        <angular>0.000000</angular>
      </velocity_decay>

      <gravity>1</gravity>

      <velocity_decay>
        <linear>0.000000</linear>
        <angular>0.000000</angular>
      </velocity_decay>

      <self_collide>0</self_collide>

      <sensor name="camera" type="depth">
        <pose>0.04 0 0.2 0 0.15 0</pose>
        <update_rate>20</update_rate>
        <visualize>true</visualize>
        <always_on>1</always_on>
        <camera>
          <horizontal_fov>1.047198</horizontal_fov>
          <image>
            <width>640</width>
            <height>480</height>
            <format>R8G8B8</format>
          </image>
          <clip>
            <near>0.05</near>
            <far>3</far>
          </clip>
          <depth_camera>
            <output>points</output>
          </depth_camera>
        </camera>



       <!--  <plugin name="camera" filename="libgazebo_ros_depth_camera.so"> 
           <alwayson>true</alwayson>
                <updaterate>30.0</updaterate>
                <cameraname>cameraLeft</cameraname>
                <framename>camera_link</framename>                  
            <imagetopicname>CameraLeft/rgb/image_raw</imagetopicname>
            <depthimagetopicname>CameraLeft/depth/image_raw</depthimagetopicname>
            <pointcloudtopicname>CameraLeft/depth/points</pointcloudtopicname>
            <camerainfotopicname>CameraLeft/rgb/camera_info</camerainfotopicname>     
            <imageTopicName>CameraLeft</imageTopicName>
            <depthimagecamerainfotopicname>CameraLeft/depth/camera_info</depthimagecamerainfotopicname>            
            <pointcloudcutoff>0.8</pointcloudcutoff>
            <pointcloudcutoffmax>3.5</pointcloudcutoffmax>
        </plugin> -->
      <plugin name="${link_name}_controller" filename="libgazebo_ros_openni_kinect.so">
        <baseline>0.2</baseline>
        <alwaysOn>true</alwaysOn>
        <updateRate>20</updateRate>
        <cameraName>app</cameraName>
        <imageTopicName>camera/rgb/image_raw</imageTopicName>
        <cameraInfoTopicName>camera/rgb/camera_info</cameraInfoTopicName>
        <depthImageTopicName>camera/depth/image_raw</depthImageTopicName>
        <depthImageCameraInfoTopicName>camera/depth/camera_info</depthImageCameraInfoTopicName>
        <pointCloudTopicName>camera/points</pointCloudTopicName>
        <frameName>map</frameName>
        <pointCloudCutoffMax>0.5</pointCloudCutoffMax>
        <pointCloudCutoff>0.5</pointCloudCutoff>
        <!-- <distortionK1>0.00000001</distortionK1> -->
        <!-- <distortionK2>0.00000001</distortionK2> -->
        <!-- <distortionK3>0.00000001</distortionK3> -->
        <!-- <distortionT1>0.00000001</distortionT1> -->
        <!-- <distortionT2>0.00000001</distortionT2> -->
        <CxPrime>0</CxPrime>
        <Cx>0</Cx>
        <Cy>0</Cy>
        <focalLength>0</focalLength>
        <hackBaseline>0</hackBaseline>
      </plugin>
    </sensor>

      <sensor name="laser" type="ray">
        <pose>0.01 0 0.07 0 -0 0</pose>
        
        <ray>
          <scan>
            <horizontal>
              <samples>360</samples>
              <resolution>1</resolution>
              <min_angle>0</min_angle>
              <max_angle>6.28318530718</max_angle>
            </horizontal>
          </scan>
          <range>
            <min>0.08</min>
            <max>6</max>
            <resolution>0.01</resolution>
          </range>
        </ray>
        <!-- <topic>/laser_scan</topic>  -->
        <plugin name="laser" filename="libgazebo_ros_laser.so"> 
          <robotNamespace></robotNamespace>
          <topicName>/laser_scan</topicName> 
          <frameName>map</frameName> 
        </plugin>
        <always_on>1</always_on>
        <update_rate>1</update_rate>
        <visualize>true</visualize>
      </sensor>

    <sensor name="imu_sensor" type="imu">
      <always_on>true</always_on>
      <update_rate>100</update_rate>
      <visualize>true</visualize>
      <topic>__default_topic__</topic>
      <plugin filename="libgazebo_ros_imu_sensor.so" name="imu_plugin">
        <topicName>imu</topicName>
        <!-- <bodyName>imu_link</bodyName> -->
        <updateRateHZ>10.0</updateRateHZ>
        <gaussianNoise>0.0</gaussianNoise>
        <xyzOffset>0 0 0</xyzOffset>
        <rpyOffset>0 0 0</rpyOffset>
        <frameName>imu_link</frameName>
      </plugin>
      <pose>0 0 0 0 0 0</pose>
    </sensor>


      <collision name='pilar_front_right'>
        <pose>0.060000 -0.074 0.065 0.000000 -0.385398 0.200000</pose>
        <geometry>
          <box>
            <size>0.022 0.001 0.08</size>
          </box>
        </geometry>
        <surface>
          <contact>
            <ode/>
          </contact>
          <friction>
            <ode/>
          </friction>
        </surface>
      </collision>
      <visual name='pilar_front_right_visual'>
        <pose>0.060000 -0.075 0.065 0.000000 -0.385398 0.2000000</pose>
        <geometry>
          <box>
            <size>0.022 0.001 0.08</size>
          </box>
        </geometry>
        <material>
          <script>
            <name>Gazebo/Green</name>
          </script>
        </material>
      </visual>

      <collision name='pilar_front_left'>
        <pose>0.060000 0.074 0.065 0.000000 -0.385398 0.200000</pose>
        <geometry>
          <box>
            <size>0.022 0.001 0.08</size>
          </box>
        </geometry>
        <surface>
          <contact>
            <ode/>
          </contact>
          <friction>
            <ode/>
          </friction>
        </surface>
      </collision>
      <visual name='pilar_front_left_visual'>
        <pose>0.060000 0.074 0.065 0.000000 -0.385398 -0.2000000</pose>
        <geometry>
          <box>
            <size>0.022 0.001 0.08</size>
          </box>
        </geometry>
        <material>
          <script>
            <name>Gazebo/Green</name>
          </script>
        </material>
      </visual>

      <collision name='pilar_back_left'>
        <pose>-0.115 0.074 0.065 0.000000 0.585398 0.2000000</pose>
        <geometry>
          <box>
            <size>0.042 0.001 0.08</size>
          </box>
        </geometry>
        <surface>
          <contact>
            <ode/>
          </contact>
          <friction>
            <ode/>
          </friction>
        </surface>
      </collision>
      <visual name='pilar_back_left_visual'>
        <pose>-0.115 0.074 0.07 0.000000 0.585398 0.2000000</pose>
        <geometry>
          <box>
            <size>0.042 0.001 0.08</size>
          </box>
        </geometry>
        <material>
          <script>
            <name>Gazebo/Green</name>
          </script>
        </material>
      </visual>

      <collision name='pilar_back_right'>
        <pose>-0.115 -0.074 0.065 0.000000 0.585398 -0.2000000</pose>
        <geometry>
          <box>
            <size>0.042 0.001 0.08</size>
          </box>
        </geometry>
        <surface>
          <contact>
            <ode/>
          </contact>
          <friction>
            <ode/>
          </friction>
        </surface>
      </collision>
      <visual name='pilar_back_right_visual'>
        <pose>-0.115 -0.074 0.07 0.000000 0.585398 -0.2000000</pose>
        <geometry>
          <box>
            <size>0.042 0.001 0.08</size>
          </box>
        </geometry>
        <material>
          <script>
            <name>Gazebo/Green</name>
          </script>
        </material>
      </visual>

      <collision name='ceiling'>
        <pose>-0.035 0.0 0.11 1.57 0 0</pose>
        <geometry>
          <box>
            <size>0.17 0.01 0.15</size>
          </box>
        </geometry>
        <surface>
          <contact>
            <ode/>
          </contact>
          <friction>
            <ode/>
          </friction>
        </surface>
      </collision>
      <visual name='ceiling_visual'>
        <pose>-0.035 0.0 0.11 1.57 0 0</pose>
        <geometry>
          <box>
            <size>0.17 0.01 0.15</size>
          </box>
        </geometry>
        <material>
          <script>
            <name>Gazebo/Green</name>
          </script>
        </material>
      </visual>
    </link>
    <link name='back_left_wheel_link'>
      <pose>-0.160000 0.100000 -0.0500000 0.000000 0.000000 0.000000</pose>
      <inertial>
        <pose>0.000000 0.000000 0.000000 0.000000 0.000000 0.000000</pose>
        <mass>0.010000</mass>
        <inertia>
          <ixx>0.010000</ixx>
          <ixy>0.000000</ixy>
          <ixz>0.000000</ixz>
          <iyy>0.010000</iyy>
          <iyz>0.000000</iyz>
          <izz>0.010000</izz>
        </inertia>
      </inertial>
      <collision name='back_left_wheel_link_geom'>
        <pose>0.000000 0.000000 0.000000 1.570800 0.000000 0.000000</pose>
        <geometry>
          <cylinder>
            <length>0.005000</length>
            <radius>0.020000</radius>
          </cylinder>
        </geometry>
        <surface>
          <contact>
            <ode/>
          </contact>
          <friction>
            <ode/>
          </friction>
        </surface>
      </collision>
      <visual name='back_left_wheel_link_visual'>
        <pose>0.000000 0.000000 0.000000 1.570800 0.000000 0.000000</pose>
        <geometry>
          <cylinder>
            <length>0.005000</length>
            <radius>0.020000</radius>
          </cylinder>
        </geometry>
        <material>
          <script>
            <name>Gazebo/White</name>
          </script>
        </material>
      </visual>
      <gravity>1</gravity>
      <velocity_decay>
        <linear>0.000000</linear>
        <angular>0.000000</angular>
      </velocity_decay>
      <self_collide>0</self_collide>
    </link>
    <joint name='back_left_wheel_joint' type='revolute'>
      <child>back_left_wheel_link</child>
      <parent>base_link</parent>
      <axis>
        <xyz>0.000000 1.000000 0.000000</xyz>
        <limit>
          <lower>-10000000000000000.000000</lower>
          <upper>10000000000000000.000000</upper>
        </limit>
        <!-- <dynamics/> -->
      </axis>
    </joint>
    <link name='back_right_wheel_link'>
      <pose>-0.160000 -0.100000 -0.0500000 0.000000 0.000000 0.000000</pose>
      <inertial>
        <pose>0.000000 0.000000 0.000000 0.000000 0.000000 0.000000</pose>
        <mass>0.010000</mass>
        <inertia>
          <ixx>0.010000</ixx>
          <ixy>0.000000</ixy>
          <ixz>0.000000</ixz>
          <iyy>0.010000</iyy>
          <iyz>0.000000</iyz>
          <izz>0.010000</izz>
        </inertia>
      </inertial>
      <collision name='back_right_wheel_link_geom'>
        <pose>0.000000 0.000000 0.000000 1.570800 0.000000 0.000000</pose>
        <geometry>
          <cylinder>
            <length>0.005000</length>
            <radius>0.020000</radius>
          </cylinder>
        </geometry>
        <surface>
          <contact>
            <ode/>
          </contact>
          <friction>
            <ode/>
          </friction>
        </surface>
      </collision>
      <visual name='back_right_wheel_link_visual'>
        <pose>0.000000 0.000000 0.000000 1.570800 0.000000 0.000000</pose>
        <geometry>
          <cylinder>
            <length>0.005000</length>
            <radius>0.020000</radius>
          </cylinder>
        </geometry>
        <material>
          <script>
            <name>Gazebo/White</name>
          </script>
        </material>
      </visual>
      <gravity>1</gravity>
      <velocity_decay>
        <linear>0.000000</linear>
        <angular>0.000000</angular>
      </velocity_decay>
      <self_collide>0</self_collide>
    </link>
    <joint name='back_right_wheel_joint' type='revolute'>
      <child>back_right_wheel_link</child>
      <parent>base_link</parent>
      <axis>
        <xyz>0.000000 1.000000 0.000000</xyz>
        <limit>
          <lower>-10000000000000000.000000</lower>
          <upper>10000000000000000.000000</upper>
        </limit>
        <!-- <dynamics/> -->
      </axis>
    </joint>
    <link name='front_left_bar_link'>
      <pose>0.160000 0.060000 -0.0500000 0.000000 0.000000 0.000000</pose>
      <inertial>
        <pose>0.000000 0.000000 0.000000 0.000000 0.000000 0.000000</pose>
        <mass>0.010000</mass>
        <inertia>
          <ixx>0.010000</ixx>
          <ixy>0.000000</ixy>
          <ixz>0.000000</ixz>
          <iyy>0.010000</iyy>
          <iyz>0.000000</iyz>
          <izz>0.010000</izz>
        </inertia>
      </inertial>
      <collision name='front_left_bar_link_geom'>
        <pose>-0.020000 0.000000 0.000000 0.000000 0.000000 0.000000</pose>
        <geometry>
          <box>
            <size>0.040000 0.020000 0.005000</size>
          </box>
        </geometry>
        <surface>
          <contact>
            <ode/>
          </contact>
          <friction>
            <ode/>
          </friction>
        </surface>
      </collision>
      <visual name='front_left_bar_link_visual'>
        <pose>-0.020000 0.000000 0.000000 0.000000 0.000000 0.000000</pose>
        <geometry>
          <box>
            <size>0.040000 0.020000 0.005000</size>
          </box>
        </geometry>
        <material>
          <script>
            <name>Gazebo/Red</name>
          </script>
        </material>
      </visual>
      <gravity>1</gravity>
      <velocity_decay>
        <linear>0.000000</linear>
        <angular>0.000000</angular>
      </velocity_decay>
      <self_collide>0</self_collide>
    </link>
    <joint name='front_left_bar_joint' type='revolute'>
      <child>front_left_bar_link</child>
      <parent>base_link</parent>
      <axis>
        <xyz>0.000000 0.000000 1.000000</xyz>
        <limit>
          <lower>-0.500000</lower>
          <upper>0.500000</upper>
        </limit>
        <!-- <dynamics/> -->
      </axis>
    </joint>
    <link name='front_left_wheel_link'>
      <pose>0.160000 0.100000 -0.0500000 0.000000 0.000000 0.000000</pose>
      <inertial>
        <pose>0.000000 0.000000 0.000000 0.000000 0.000000 0.000000</pose>
        <mass>0.010000</mass>
        <inertia>
          <ixx>0.010000</ixx>
          <ixy>0.000000</ixy>
          <ixz>0.000000</ixz>
          <iyy>0.010000</iyy>
          <iyz>0.000000</iyz>
          <izz>0.010000</izz>
        </inertia>
      </inertial>
      <collision name='front_left_wheel_link_geom'>
        <pose>0.000000 0.000000 0.000000 1.570800 0.000000 0.000000</pose>
        <geometry>
          <cylinder>
            <length>0.005000</length>
            <radius>0.020000</radius>
          </cylinder>
        </geometry>
        <surface>
          <contact>
            <ode/>
          </contact>
          <friction>
            <ode/>
          </friction>
        </surface>
      </collision>
      <visual name='front_left_wheel_link_visual'>
        <pose>0.000000 0.000000 0.000000 1.570800 0.000000 0.000000</pose>
        <geometry>
          <cylinder>
            <length>0.005000</length>
            <radius>0.020000</radius>
          </cylinder>
        </geometry>
        <material>
          <script>
            <name>Gazebo/White</name>
          </script>
        </material>
      </visual>
      <gravity>1</gravity>
      <velocity_decay>
        <linear>0.000000</linear>
        <angular>0.000000</angular>
      </velocity_decay>
      <self_collide>0</self_collide>
    </link>
    <joint name='front_left_wheel_joint' type='revolute'>
      <child>front_left_wheel_link</child>
      <parent>front_left_bar_link</parent>
      <axis>
        <xyz>0.000000 1.000000 0.000000</xyz>
        <limit>
          <lower>-10000000000000000.000000</lower>
          <upper>10000000000000000.000000</upper>
        </limit>
        <dynamics/>
      </axis>
    </joint>
    <link name='front_right_bar_link'>
      <pose>0.160000 -0.060000 -0.0500000 0.000000 0.000000 0.000000</pose>
      <inertial>
        <pose>0.000000 0.000000 0.000000 0.000000 0.000000 0.000000</pose>
        <mass>0.010000</mass>
        <inertia>
          <ixx>0.010000</ixx>
          <ixy>0.000000</ixy>
          <ixz>0.000000</ixz>
          <iyy>0.010000</iyy>
          <iyz>0.000000</iyz>
          <izz>0.010000</izz>
        </inertia>
      </inertial>
      <collision name='front_right_bar_link_geom'>
        <pose>-0.020000 0.000000 0.000000 0.000000 0.000000 0.000000</pose>
        <geometry>
          <box>
            <size>0.040000 0.020000 0.005000</size>
          </box>
        </geometry>
        <surface>
          <contact>
            <ode/>
          </contact>
          <friction>
            <ode/>
          </friction>
        </surface>
      </collision>
      <visual name='front_right_bar_link_visual'>
        <pose>-0.020000 0.000000 0.000000 0.000000 0.000000 0.000000</pose>
        <geometry>
          <box>
            <size>0.040000 0.020000 0.005000</size>
          </box>
        </geometry>
        <material>
          <script>
            <name>Gazebo/Red</name>
          </script>
        </material>
      </visual>
      <gravity>1</gravity>
      <velocity_decay>
        <linear>0.000000</linear>
        <angular>0.000000</angular>
      </velocity_decay>
      <self_collide>0</self_collide>
    </link>
    <joint name='front_right_bar_joint' type='revolute'>
      <child>front_right_bar_link</child>
      <parent>base_link</parent>
      <axis>
        <xyz>0.000000 0.000000 1.000000</xyz>
        <limit>
          <lower>-0.500000</lower>
          <upper>0.500000</upper>
        </limit>
        <dynamics/>
      </axis>
    </joint>
    <link name='front_right_wheel_link'>
      <pose>0.160000 -0.100000 -0.0500000 0.000000 0.000000 0.000000</pose>
      <inertial>
        <pose>0.000000 0.000000 0.000000 0.000000 0.000000 0.000000</pose>
        <mass>0.010000</mass>
        <inertia>
          <ixx>0.010000</ixx>
          <ixy>0.000000</ixy>
          <ixz>0.000000</ixz>
          <iyy>0.010000</iyy>
          <iyz>0.000000</iyz>
          <izz>0.010000</izz>
        </inertia>
      </inertial>
      <collision name='front_right_wheel_link_geom'>
        <pose>0.000000 0.000000 0.000000 1.570800 0.000000 0.000000</pose>
        <geometry>
          <cylinder>
            <length>0.005000</length>
            <radius>0.020000</radius>
          </cylinder>
        </geometry>
        <surface>
          <contact>
            <ode/>
          </contact>
          <friction>
            <ode/>
          </friction>
        </surface>
      </collision>
      <visual name='front_right_wheel_link_visual'>
        <pose>0.000000 0.000000 0.000000 1.570800 0.000000 0.000000</pose>
        <geometry>
          <cylinder>
            <length>0.005000</length>
            <radius>0.020000</radius>
          </cylinder>
        </geometry>
        <material>
          <script>
            <name>Gazebo/White</name>
          </script>
        </material>
      </visual>
      <gravity>1</gravity>
      <velocity_decay>
        <linear>0.000000</linear>
        <angular>0.000000</angular>
      </velocity_decay>
      <self_collide>0</self_collide>
    </link>
    <joint name='front_right_wheel_joint' type='revolute'>
      <child>front_right_wheel_link</child>
      <parent>front_right_bar_link</parent>
      <axis>
        <xyz>0.000000 1.000000 0.000000</xyz>
        <limit>
          <lower>-10000000000000000.000000</lower>
          <upper>10000000000000000.000000</upper>
        </limit>
        <dynamics/>
      </axis>
    </joint>
    <link name='steer_link'>
      <pose>0.160000 0.000000 -0.0500000 0.000000 0.000000 0.000000</pose>
      <inertial>
        <pose>0.000000 0.000000 0.000000 0.000000 0.000000 0.000000</pose>
        <mass>0.010000</mass>
        <inertia>
          <ixx>0.010000</ixx>
          <ixy>0.000000</ixy>
          <ixz>0.000000</ixz>
          <iyy>0.010000</iyy>
          <iyz>0.000000</iyz>
          <izz>0.010000</izz>
        </inertia>
      </inertial>
      <collision name='steer_link_geom'>
        <pose>0.020000 0.000000 0.000000 0.000000 0.000000 0.000000</pose>
        <geometry>
          <box>
            <size>0.040000 0.020000 0.005000</size>
          </box>
        </geometry>
        <surface>
          <contact>
            <ode/>
          </contact>
          <friction>
            <ode/>
          </friction>
        </surface>
      </collision>
      <visual name='steer_link_visual'>
        <pose>-0.020000 0.000000 0.000000 0.000000 0.000000 0.000000</pose>
        <geometry>
          <box>
            <size>0.040000 0.020000 0.005000</size>
          </box>
        </geometry>
        <material>
          <script>
            <name>Gazebo/Red</name>
          </script>
        </material>
      </visual>
      <gravity>1</gravity>
      <velocity_decay>
        <linear>0.000000</linear>
        <angular>0.000000</angular>
      </velocity_decay>
      <self_collide>0</self_collide>
    </link>
    <joint name='steer_joint' type='revolute'>
      <child>steer_link</child>
      <parent>base_link</parent>
      <axis>
        <xyz>0.000000 0.000000 1.000000</xyz>
        <limit>
          <lower>-0.500000</lower>
          <upper>0.500000</upper>
        </limit>
        <dynamics/>
      </axis>
    </joint>
    <link name='ackermann_bar_link'>
      <pose>0.120000 0.000000 -0.0500000 0.000000 0.000000 0.000000</pose>
      <inertial>
        <pose>0.000000 0.000000 0.000000 0.000000 0.000000 0.000000</pose>
        <mass>0.010000</mass>
        <inertia>
          <ixx>0.010000</ixx>
          <ixy>0.000000</ixy>
          <ixz>0.000000</ixz>
          <iyy>0.010000</iyy>
          <iyz>0.000000</iyz>
          <izz>0.010000</izz>
        </inertia>
      </inertial>
      <collision name='ackermann_bar_link_geom'>
        <pose>0.000000 0.000000 0.000000 0.000000 0.000000 0.000000</pose>
        <geometry>
          <box>
            <size>0.020000 0.150000 0.010000</size>
          </box>
        </geometry>
        <surface>
          <contact>
            <ode/>
          </contact>
          <friction>
            <ode/>
          </friction>
        </surface>
      </collision>
      <visual name='ackermann_bar_link_visual'>
        <pose>0.000000 0.000000 0.000000 0.000000 0.000000 0.000000</pose>
        <geometry>
          <box>
            <size>0.020000 0.150000 0.010000</size>
          </box>
        </geometry>
        <material>
          <script>
            <name>Gazebo/Blue</name>
          </script>
        </material>
      </visual>
      <gravity>1</gravity>
      <velocity_decay>
        <linear>0.000000</linear>
        <angular>0.000000</angular>
      </velocity_decay>
      <self_collide>0</self_collide>
    </link>
    <joint name='ackermann_joint' type='revolute'>
      <child>ackermann_bar_link</child>
      <parent>steer_link</parent>
      <axis>
        <xyz>0.000000 0.000000 1.000000</xyz>
        <limit>
          <lower>-0.500000</lower>
          <upper>0.500000</upper>
        </limit>
        <dynamics/>
      </axis>
    </joint>
    <joint name='ackermann_left_bar_joint' type='revolute'>
      <parent>front_left_bar_link</parent>
      <child>ackermann_bar_link</child>
      <axis>
        <xyz>0.000000 0.000000 1.000000</xyz>
        <limit>
          <lower>-10000000000000000.000000</lower>
          <upper>10000000000000000.000000</upper>
        </limit>
        <dynamics/>
      </axis>
      <pose>0.000000 0.060000 0.000000 0.000000 0.000000 0.000000</pose>
    </joint>
    <joint name='ackermann_right_bar_joint' type='revolute'>
      <parent>front_right_bar_link</parent>
      <child>ackermann_bar_link</child>
      <axis>
        <xyz>0.000000 0.000000 1.000000</xyz>
        <limit>
          <lower>-10000000000000000.000000</lower>
          <upper>10000000000000000.000000</upper>
        </limit>
        <dynamics/>
      </axis>
      <pose>0.000000 -0.060000 0.000000 0.000000 0.000000 0.000000</pose>
    </joint>

    <include>
      <uri>model://kinect</uri>
      <pose>0.04 0 0.14 0 0.1 0</pose>

  <!--     <sensor name="camera" type="depth">
        <update_rate>20</update_rate>
        <visualize>true</visualize>
        <always_on>1</always_on>
        <camera>
          <horizontal_fov>1.047198</horizontal_fov>
          <image>
            <width>640</width>
            <height>480</height>
            <format>R8G8B8</format>
          </image>
          <clip>
            <near>0.05</near>
            <far>3</far>
          </clip>
          <depth_camera>
            <output>points</output>
          </depth_camera>
        </camera>



        <plugin name="camera" filename="libgazebo_ros_depth_camera.so"> 
          <robotNamespace></robotNamespace>
          <topicName>/depth_camera</topicName> 
          <frameName>map</frameName> 
        </plugin>

      </sensor>
 -->

    </include>

    <joint name="kinect_rack" type="revolute">
      <parent>kinect::link</parent>
      <child>base_link
      </child>
      <axis>
        <xyz>1 0 0</xyz>
        <limit>
          <lower>0</lower>
          <upper>0</upper>
        </limit>
        <use_parent_model_frame>true</use_parent_model_frame>
      </axis>
    </joint>
    <plugin name="test_control" filename="libautonomos_plugin.so">
      <debug>True</debug>
    <!-- <plugin name="gazebo_ros_control" filename="libgazebo_ros_control.so"> -->
      <!-- <robotParam>robot_description</robotParam> -->
      <!-- <robotNamespace>ackermann</robotNamespace> -->
      <!-- <robotNamespace>/robot_description</robotNamespace> -->
      <!-- <robotSimType>gazebo_ros_control/DefaultRobotHWSim</robotSimType> -->
    </plugin>

    <static>0</static>
    <pose>0.000000 0.000000 0.25 0.000000 0.000000 0.000000</pose>



  </model>
</sdf>
